Workbook

Sheet Overview
A1: ccc
B2: Key | F2: Example | I2: Key Focus | J2: KPI (Monthly)
B3: Tier 1 | C3: Top International Media Outlets | F3: Forbes, Bloomberg etc. | H3: Shoaib | I3: Target Tier 1 Media with macro news | J3: 2 Micro-papers + 5 Tier 1 mentions
B4: Tier 2 | C4: Regional Media Outlets | F4: The National, Khaleej | H4: Ameerah | I4: Lifestyle + Reach outs (Radio/Podcast/Lunches) | J4: 2 Top 50 Mentions + 4radio/podcast appearances
B5: Tier 3 | C5: International mentions from small outlets | H5: Jade | I5: Real estate general content | J5: 30 mentiones + Beat our competitors
B8: Period | C8: Tier 1 | D8: Tier 2 | E8: Tier 3 | F8: Total Mentions
B9: 2021 | C9: - | D9: 19 | E9: 12 | F9: =D9+E9 -> 31
B10: 2022 | C10: =COUNTIFS('2022'!$B:$B,C$8) -> 19 | D10: =COUNTIFS('2022'!$B:$B,D$8) -> 121 | E10: =COUNTIFS('2022'!$B:$B,E$8) -> 62 | F10: =D10+E10 -> 183
B11: 2023 | C11: =COUNTIFS('2023'!$B:$B,C$8) -> 39 | D11: =COUNTIFS('2023'!$B:$B,D$8) -> 139 | E11: =COUNTIFS('2023'!$B:$B,E$8) -> 108 | F11: =SUM(C11:E11) -> 286
B12: 2024 | C12: =COUNTIFS('2024'!$B:$B,C$8) -> 7 | D12: =COUNTIFS('2024'!$B:$B,D$8) -> 125 | E12: =COUNTIFS('2024'!$B:$B,E$8) -> 78 | F12: =SUM(C12:E12) -> 210 | I12: 2024 - 210 | J12: 210
B13: 2025 | C13: =COUNTIFS('2025'!$C:$C,C$8) -> 0 | D13: =COUNTIFS('2025'!$C:$C,D$8) -> 77 | E13: =COUNTIFS('2025'!$C:$C,E$8) -> 119 | F13: =SUM(C13:E13) -> 196 | I13: 2025 - Nov -
B27: Period | C27: Tier 1 | D27: Tier 2 | E27: Tier 3
B28: 2022 H1 | C28: =COUNTIFS('2022'!$B:$B,C$8,'2022'!$A:$A,"<"&DATE(2022,7,1)) -> 3 | D28: =COUNTIFS('2022'!$B:$B,D$8,'2022'!$A:$A,"<"&DATE(2022,7,1)) -> 27 | E28: =COUNTIFS('2022'!$B:$B,E$8,'2022'!$A:$A,"<"&DATE(2022,7,1)) -> 11
B29: 2023 H1 | C29: =COUNTIFS('2023'!$B:$B,C$8,'2023'!$A:$A,"<"&DATE(2023,7,1)) -> 27 | D29: =COUNTIFS('2023'!$B:$B,D$8,'2023'!$A:$A,"<"&DATE(2023,7,1)) -> 58 | E29: =COUNTIFS('2023'!$B:$B,E$8,'2023'!$A:$A,"<"&DATE(2023,7,1)) -> 65
B30: Change | C30: =C29/C28-1 -> 8 | D30: =D29/D28-1 -> 1.1481481 | E30: =E29/E28-1 -> 4.9090909
B33: Core
B34: Period | C34: Tier 1 | D34: Tier 2 | E34: Tier 3
B35: 2022 H1 | C35: =COUNTIFS('2022'!$B:$B,C$8,'2022'!$A:$A,"<"&DATE(2022,7,1),'2022'!$F:$F,"Betterhomes") -> 3 | D35: =COUNTIFS('2022'!$B:$B,D$8,'2022'!$A:$A,"<"&DATE(2022,7,1),'2022'!$F:$F,"Betterhomes") -> 18 | E35: =COUNTIFS('2022'!$B:$B,E$8,'2022'!$A:$A,"<"&DATE(2022,7,1),'2022'!$F:$F,"Betterhomes") -> 9
B36: 2023 H1 | C36: =COUNTIFS('2023'!$B:$B,C$8,'2023'!$A:$A,"<"&DATE(2023,7,1),'2023'!$F:$F,"Betterhomes") -> 26 | D36: =COUNTIFS('2023'!$B:$B,D$8,'2023'!$A:$A,"<"&DATE(2023,7,1),'2023'!$F:$F,"Betterhomes") -> 50 | E36: =COUNTIFS('2023'!$B:$B,E$8,'2023'!$A:$A,"<"&DATE(2023,7,1),'2023'!$F:$F,"Betterhomes") -> 65
B37: Change | C37: =C36/C35-1 -> 7.6666667 | D37: =D36/D35-1 -> 1.7777778 | E37: =E36/E35-1 -> 6.2222222
B40: Prime
B41: Period | C41: Tier 1 | D41: Tier 2 | E41: Tier 3
B42: 2022 H1 | C42: =COUNTIFS('2022'!$B:$B,C$8,'2022'!$A:$A,"<"&DATE(2022,7,1),'2022'!F:F,"PRIME") -> 0 | D42: =COUNTIFS('2022'!$B:$B,D$8,'2022'!$A:$A,"<"&DATE(2022,7,1),'2022'!F:F,"PRIME") -> 0 | E42: =COUNTIFS('2022'!$B:$B,E$8,'2022'!$A:$A,"<"&DATE(2022,7,1),'2022'!F:F,"PRIME") -> 0
B43: 2023 H1 | C43: =COUNTIFS('2023'!$B:$B,C$8,'2023'!$A:$A,"<"&DATE(2023,7,1),'2023'!$F:$F,"Prime by Betterhomes") -> 1 | D43: =COUNTIFS('2023'!$B:$B,D$8,'2023'!$A:$A,"<"&DATE(2023,7,1),'2023'!$F:$F,"Prime by Betterhomes") -> 7 | E43: =COUNTIFS('2023'!$B:$B,E$8,'2023'!$A:$A,"<"&DATE(2023,7,1),'2023'!$F:$F,"Prime by Betterhomes") -> 0
B44: Change | C44: =C43/C42-1 -> #DIV/0! | D44: =D43/D42-1 -> #DIV/0! | E44: =E43/E42-1 -> #DIV/0!
B46: Period | C46: Tier 1 | D46: Tier 2 | E46: Tier 3 | F46: Total Mentions
B47: January | C47: 5 | D47: 8 | E47: 26 | F47: 39
B48: February | C48: 5 | D48: 8 | E48: 14 | F48: 27
B49: March | C49: 6 | D49: 12 | E49: 5 | F49: 23
B50: April | C50: 4 | D50: 8 | E50: 4 | F50: 16
B51: May | C51: 0 | D51: 10 | E51: 6 | F51: 16
B52: June | C52: 7 | D52: 12 | E52: 10 | F52: 29
B53: July | C53: 2 | D53: 25 | E53: 5 | F53: 32
B54: August | C54: 2 | D54: 9 | E54: 2 | F54: 13
B55: September | C55: 0 | D55: 7 | E55: 7 | F55: 16
B56: October | C56: 1 | D56: 18 | E56: 3 | F56: 22
B57: November | C57: 6 | D57: 12 | E57: 14 | F57: 32
B58: December | C58: 1 | D58: 8 | E58: 12 | F58: 21
B60: Key points
B61: We are just half way through the year and I already have more mentions from Tier one outlets than the whole of last year
...

Sheet 2026
A1: cc | B1: Media Tier | C1: Media | D1: Cost | E1: Reach | F1: Title | G1: Link | H1: Link | I1: Brand
A2: 46023 | B2: Tier 1 Local | C2: Khaleej Times | D2: 2200 | E2: 500000 | F2: Dubai South to draw more end-users as DWC expansion creates more jobs | G2: https://www.khaleejtimes.com/uae/dubai-south-properties-dwc-expansion
A3: 46030 | B3: Tier 1 Local | C3: Khaleej Times | D3: 2200 | E3: 500000 | F3: Dubai real estate outlook 2026: steady demand, selective cooling, and a tech‑driven turn | G3: https://www.khaleejtimes.com/business/property/dubai-real-estate-outlook-2026-steady-demand-selective-cooling-and-a-techdriven-turn | I3: betterhomes
A4: 46034 | B4: Tier 1 Local | C4: Khaleej Times | D4: 2200 | E4: 500000 | F4: Why Dubai’s property boom is built to last for a long time | G4: https://www.khaleejtimes.com/business/property/why-dubais-property-boom-is-built-to-last-for-a-long-time | I4: betterhomes
A5: 46035 | B5: Tier 3 | C5: Press Reader | F5: Why Dubai’s property boom is built to last for a long time | G5: https://www.pressreader.com/uae/khaleej-times/20260112/281788520445913
A6: 46035 | B6: Tier 1 Local | C6: Construction Week | D6: 3000 | E6: 40000 | F6: What’s next for Dubai’s real estate landscape? | G6: https://www.constructionweekonline.com/business/insights/dubai-real-estate-2026-2
A7: 46034 | B7: Tier 2 | C7: Zawya | D7: 1000 | E7: 100000 | F7: The 3rd edition of Dubai's Top 50 Homes revealed - ZAWYA | G7: The 3rd edition of Dubai's Top 50 Homes revealed - ZAWYA
A8: 15 Januaury 2026 | B8: Tier 2 | C8: Zawya | D8: 1000 | E8: 100000 | F8: Dubai records strongest residential year in 2025; nets $149bln in sales | G8: https://www.tradingview.com/news/reuters.com,2026-01-15:newsml_Zaw6LVJmF:0-zawya-sng-dubai-records-strongest-residential-year-in-2025-nets-149bln-in-sales/ | I8: betterhomes
A9: 46036 | B9: Tier 1 Local | C9: Arabian Business | D9: 9500 | E9: 250000 | F9: Dubai property market hits record $149bn in 2025 as demand and prices strengthen | G9: https://www.arabianbusiness.com/industries/real-estate/dubai-property-market-hits-record-149bn-in-2025-as-demand-and-prices-strengthen | I9: betterhomes
A10: 46036 | B10: Tier 1 Local | C10: Khaleej Times | D10: 2200 | E10: 500000 | F10: Dubai closes 2025 with a record Dh547b property market | G10: https://www.khaleejtimes.com/business/property/dubai-closes-2025-with-a-record-dh547b-property-market?amp=1
A11: 46039 | B11: Tier 1 Local | C11: Khaleej Times | D11: 2200 | E11: 500000 | F11: The off-plan segment will not only continue to dominate, but also increase its share in the Dubai property market | G11: https://www.khaleejtimes.com/business/property/dubai-properties-buying-off-plan-2026
A12: 46042 | B12: Tier 1 Local | C12: Construction Week | D12: 3000 | E12: 40000 | F12: Dubai property market 2026: Where are smart investors looking next? | G12: Dubai property market 2026: Where are smart investors looking next?
A13: 46044 | B13: Tier 1 Local | C13: Construction Week | D13: 3000 | E13: 40000 | F13: Dubai property market 2025-26: Questions global investors are asking right now | G13: https://www.constructionweekonline.com/analysis/dubai-property-market-2026
A14: 46050 | B14: Tier 1 Local | C14: Construction Week | D14: 3000 | E14: 40000 | F14: betterhomes appoints Alex Leigh as Director of Operations | G14: https://www.constructionweekonline.com/people/appointments/betterhomes-alex-leigh
A15: 46051 | B15: Tier 3 | C15: The Economic Times | F15: Indians, Britons top Dubai property buys in 2025 as rupee falls | G15: https://economictimes.indiatimes.com/nri/invest/indians-britons-top-dubai-property-buys-in-2025-as-rupee-falls/articleshow/127730830.cms?from=mdr&utm_source=contentofinterest&utm_medium=text&utm_campaign=cppstt
A16: 46051 | B16: Tier 2 | C16: Zawya | D16: 1000 | E16: 100000 | F16: Dubai rental boom defies inflation as demand surges but rents stay flat | G16: https://www.tradingview.com/news/reuters.com,2026-01-29:newsml_Zaw4HPJHJ:0-zawya-pressr-dubai-rental-boom-defies-inflation-as-demand-surges-but-rents-stay-flat/
A17: 46052 | B17: Tier 1 Local | C17: Khaleej Times | D17: 2200 | E17: 500000 | F17: Dubai rents hold steady as families reshape demand in record‑setting 2025 | Khaleej Times | G17: Dubai rents hold steady as families reshape demand in record‑setting 2025 | Khaleej Times
A18: 46058 | B18: Tier 1 Local | C18: Arabian Business | D18: 9500 | E18: 250000 | F18: Dubai off-plan homes dominate property market with record 65% of transactions | G18: Dubai off-plan homes dominate property market with record 65% of transactions
A19: 46058 | B19: Tier 1 Local | C19: Construction Week | D19: 3000 | E19: 40000 | F19: 132,000 homes sold: Dubai’s off-plan sales reach $78 bn in 2025 | G19: 132,000 homes sold: Dubai’s off-plan sales reach $78 bn in 2025
A20: 46058 | B20: Tier 3 | C20: Trade Arabia | F20: Dubai off-plan sales hit 130,000 homes; value touches $77.88bn - TradeArabia | G20: Dubai off-plan sales hit 130,000 homes; value touches $77.88bn - TradeArabia
A21: 46057 | B21: Tier 3 | C21: Money Control | F21: Why Indian investors are increasingly buying property in Dubai | G21: https://www.moneycontrol.com/news/business/personal-finance/why-indian-investors-are-increasingly-buying-property-in-dubai-13774469.html
A22: 46063 | B22: Tier 1 Local | C22: Construction Week | D22: 3000 | E22: 40000 | F22: Dubai’s January property sales hit AED55 bn | G22: https://www.constructionweekonline.com/analysis/dubai-january-property-sales
A23: 46063 | B23: Tier 1 Local | C23: Arabian Business | D23: 9500 | E23: 250000 | F23: Dubai residential sales hit AED55.2bn in January as transactions rise | G23: https://www.arabianbusiness.com/industries/real-estate/dubai-residential-sales-hit-aed55-2bn-in-january-as-transactions-rise
A24: 46069 | B24: Tier 2 | C24: Zawya | D24: 1000 | E24: 100000 | F24: Abu Dhabi property market records $3.2bln in January sales | G24: Abu Dhabi property market records $3.2bln in January sales
A25: 46067 | B25: Tier 1 Local | C25: Arabian Business | D25: 9500 | E25: 250000 | F25: Abu Dhabi property market hits $3.27bn in January sales as off-plan dominates 83 per cent of deals | G25: Abu Dhabi property market hits $3.27bn in January sales as off-plan dominates 83 per cent of deals
A26: 46063 | B26: Tier 1 Local | C26: Construction Week | D26: 3000 | E26: 40000 | F26: Ellington Properties unveils The Meriva Collection on Dubai Islands | G26: https://www.constructionweekonline.com/projects-tenders/ellington-properties-the-meriva
A27: 46063 | B27: Tier 2 | C27: Zawya | D27: 1000 | E27: 100000 | F27: ZAWYA-PRESSR: Ellington Properties unveils The Meriva Collection, a hospitality-led beachfront destination on Dubai Islands | G27: https://www.tradingview.com/news/reuters.com,2026-02-10:newsml_ZawPnl2M:0-zawya-pressr-ellington-properties-unveils-the-meriva-collection-a-hospitality-led-beachfront-destination-on-dubai-islands/
A28: 46063 | B28: Tier 1 Local | C28: Construction Week | D28: 3000 | E28: 40000 | F28: Abu Dhabi property market kicks off 2026 with $3.2bn sales surge - Construction Week | G28: Abu Dhabi property market kicks off 2026 with $3.2bn sales surge - Construction Week
A29: 46079 | B29: Tier 1 Local | C29: Arabian Business | D29: 9500 | E29: 250000 | F29: Dubai property sales hit $10.6bn during Ramadan 2025 as betterhomes forecasts up 12% growth in 2026 | G29: https://www.arabianbusiness.com/real-estate/dubai-property-sales-hit-10-6bn-during-ramadan-2025-as-betterhomes-forecasts-up-12-growth-in-2026
A30: 46076 | B30: Tier 3 | C30: One Ville News | F30: Blue Square Development: A trusted regional partner bringing decades of expertise to Dubai’s residential landscape | G30: https://onevillenews.com/2026/02/23/blue-square-development-a-trusted-regional-partner-bringing-decades-of-expertise-to-dubais-residential-landscape/
A31: 46078 | B31: Tier 1 Local | C31: Arabian Business | D31: 9500 | E31: 250000 | F31: Dubai property sales hit $10.6bn during Ramadan 2025 as betterhomes forecasts up 12% growth in 2026 | G31: https://www.arabianbusiness.com/real-estate/dubai-property-sales-hit-10-6bn-during-ramadan-2025-as-betterhomes-forecasts-up-12-growth-in-2026
A32: 46079 | B32: Tier 1 Local | C32: Khaleej Times | D32: 2200 | E32: 500000 | F32: Dubai real estate activity to rise 8–12% during Ramadan 2026 | G32: https://www.khaleejtimes.com/business/dubai-real-estate-activity-to-rise-812-during-ramadan-2026
A34: March | D34: =SUM(D18:D32) -> 63700 | E34: =SUM(E18:E32) -> 2110000
A35: 46086 | B35: Tier 1 International | C35: Reuters | D35: 20000 | E35: 1000000 | F35: UAE's property sector faces reckoning after Iran strikes | G35: https://www.reuters.com/world/middle-east/uaes-property-sector-faces-reckoning-after-iran-strikes-2026-03-05/
A36: 46090 | B36: Tier 1 Local | C36: Arabian Business | D36: 9500 | E36: 250000 | F36: Dubai property market remains active despite dip in enquiries: betterhomes | G36: https://www.arabianbusiness.com/real-estate/dubai-property-market-active
A37: 46090 | B37: Tier 3 | C37: MENAFN | F37: Dubai Property Market Continues To Move Despite Quieter Conditions, Says Betterhomes | G37: Dubai Property Market Continues To Move Despite Quieter Conditions, Says Betterhomes
A38: 46092 | B38: Tier 1 Local | C38: The National News | D38: 9300 | E38: 200000 | F38: Stability, not panic': Dubai real estate companies have faith despite Iran war | The National | G38: Stability, not panic': Dubai real estate companies have faith despite Iran war | The National
A39: 46093 | B39: Tier 1 Local | C39: Gulf Business Daily | D39: 1000 | E39: 100000 | F39: UAE Business: Dubai's leasing market continues to move despite regional uncertainty, says expert | G39: UAE Business: Dubai's leasing market continues to move despite regional uncertainty, says expert
A40: 46093 | B40: Tier 1 Local | C40: Khaleej Times | D40: 2200 | E40: 500000 | F40: Dubai property defies uncertainty: Investors prioritise stability - Khaleej Times | G40: Dubai property defies uncertainty: Investors prioritise stability - Khaleej Times
A41: 46094 | B41: Tier 2 | C41: MSN | F41: Dubai rental market weathers regional tensions with flexible payment plans - MSN | G41: Dubai rental market weathers regional tensions with flexible payment plans - MSN
...

Sheet 2026 Overview
A1: 2025 | C1: January | D1: February | E1: March | F1: April | G1: May | H1: June | I1: July | J1: August | K1: September | L1: October | M1: November | N1: December
A2: BH | B2: Tier 1 Intl
B3: Tier 1 Local
B4: Tier 2
B5: Tier 3
B6: Grand Total
A8: Competitor Press Mentions | C8: January | D8: February | E8: March | F8: April | G8: May | H8: June | I8: July | J8: August | K8: September | L8: October | M8: November | N8: December
A9: BH
A10: Allsopp&Allsopp
A11: Haus&Haus
A12: Engel&Volkers

Sheet 2025
A1: Month | B1: Date | C1: Media Tier | D1: Media | E1: Cost | F1: Reach | G1: Title | H1: Link | I1: Link | J1: Brand
A2: =TEXT(B2, "MMMM") -> January | B2: 45658 | C2: Tier 2 | D2: AGBI | E2: 1000 | F2: 30000 | G2: Burj Khalifa at 15: Ups and downs of the world's tallest skyscraper | H2: https://www.agbi.com/real-estate/2025/01/burj-khalifa-at-15-ups-and-downs-of-the-worlds-tallest-skyscraper/ | I2: {=HYPERLINK(H2:H1086, "ARTICLELINK")} -> #REF! | J2: Betterhomes
A3: =TEXT(B3, "MMMM") -> January | B3: 45661 | C3: Tier 1 Local | D3: Khaleej Times | E3: 2200 | F3: 500000 | G3: Burj Khalifa turns 15: How much it costs to rent a home at the world's tallest building in Dubai | H3: https://www.khaleejtimes.com/uae/burj-khalifa-turns-15-how-much-it-costs-to-rent-a-home-at-the-worlds-tallest-building-in-dubai | J3: Betterhomes
A4: =TEXT(B4, "MMMM") -> January | B4: 45662 | C4: Tier 3 | D4: MSN | G4: Dubai's Burj Khalifa charges Rs 70061 per sq ft in annual rent; here's how much it costs to rent a 1-bedroom flat in world's tallest building | H4: https://www.msn.com/en-in/money/topstories/dubai-s-burj-khalifa-charges-rs-70061-per-sq-ft-in-annual-rent-here-s-how-much-it-costs-to-rent-a-1-bedroom-flat-in-world-s-tallest-building/ar-AA1wXCUw?ocid=finance-verthp-feeds | J4: Betterhomes
A5: =TEXT(B5, "MMMM") -> January | B5: 45666 | C5: Tier 1 Local | D5: Construction Week | E5: 3000 | F5: 40000 | G5: Betterhomes CEO steps down, takes over as Cencorp boss | H5: https://www.constructionweekonline.com/news/betterhomes-ceo-steps-down-takes-over-as-cencorp-boss | J5: Betterhomes/Cencorp
A6: =TEXT(B6, "MMMM") -> January | B6: 45666 | C6: Tier 1 Local | D6: Arabian Business | E6: 9500 | F6: 250000 | G6: Dubai real estate firm Betterhomes announces two major leadership changes | H6: https://www.arabianbusiness.com/jobs/dubai-real-estate-firm-betterhomes-announces-two-major-leadership-changes | J6: Betterhomes/Cencorp
A7: =TEXT(B7, "MMMM") -> January | B7: 45666 | C7: Tier 3 | D7: The Arabian Marketer | G7: Betterhomes Has Announced Two Major Leadership Changes | H7: https://arabianmarketer.ae/betterhomes-has-announced-two-major-leadership-changes/ | J7: Betterhomes/Cencorp
A8: =TEXT(B8, "MMMM") -> January | B8: 45666 | C8: Tier 2 | D8: Zawya | E8: 1000 | F8: 100000 | G8: Betterhomes has announced two major leadership changes | H8: https://www.zawya.com/en/press-release/people-in-the-news/betterhomes-has-announced-two-major-leadership-changes-eul65s4o | J8: Betterhomes/Cencorp
A9: =TEXT(B9, "MMMM") -> January | B9: 45667 | C9: Tier 3 | D9: The Globe and Mail | G9: Betterhomes Reveals Dubai as the World’s Premier Property Investment Destination | H9: https://www.theglobeandmail.com/investing/markets/markets-news/Plentisoft/30388136/betterhomes-reveals-dubai-as-the-worlds-premier-property-investment-destination/ | J9: Betterhomes
A10: =TEXT(B10, "MMMM") -> January | B10: 45668 | C10: Tier 3 | D10: Travel and Tour World | G10: Richard Waind Becomes CEO of Cencorp, While Louis Harding Takes Over as Betterhomes CEO to Drive Dubai Real Estate Growth | H10: https://www.travelandtourworld.com/news/article/richard-waind-becomes-ceo-of-cencorp-while-louis-harding-takes-over-as-betterhomes-ceo-to-drive-dubai-real-estate-growth/ | J10: Betterhomes/Cencorp
A11: =TEXT(B11, "MMMM") -> January | B11: 45668 | C11: Tier 3 | D11: Markets Insider | G11: Betterhomes Reveals Dubai as the World’s Premier Property Investment Destination | H11: https://markets.businessinsider.com/news/stocks/betterhomes-reveals-dubai-as-the-world-s-premier-property-investment-destination-1034215635 | J11: Betterhomes
A12: =TEXT(B12, "MMMM") -> January | B12: 45670 | C12: Tier 3 | D12: Street Insider | G12: Betterhomes Reveals Dubai as the World’s Premier Property Investment Destination | H12: https://www.streetinsider.com/Evertise+Financial/Betterhomes+Reveals+Dubai+as+the+World%E2%80%99s+Premier+Property+Investment+Destination/24196773.html | J12: Betterhomes
A13: =TEXT(B13, "MMMM") -> January | B13: 45670 | C13: Tier 3 | D13: Digital Journal | G13: Betterhomes Reveals Dubai as the World’s Premier Property Investment Destination | H13: https://www.digitaljournal.com/pr/news/vehement-media/betterhomes-reveals-dubai-world-s-premier-1912448123.html | J13: Betterhomes
A14: =TEXT(B14, "MMMM") -> January | B14: 45672 | C14: Tier 1 Local | D14: Arabian Business | E14: 9500 | F14: 250000 | G14: Dubai real estate sets record breaking transaction record with $115bn of sales in 2024; $65.5m villa and $74.8m apartment top charts | H14: https://www.arabianbusiness.com/industries/real-estate/dubai-real-estate-sets-record-breaking-transaction-record-with-115bn-of-sales-in-2024-65-5m-villa-and-74-8m-apartment-top-charts | J14: Betterhomes
A15: =TEXT(B15, "MMMM") -> January | B15: 45672 | C15: Tier 1 Local | D15: Khaleej Times | E15: 2200 | F15: 500000 | G15: Price surge may moderate as Dubai set to add 72,000 housing units | H15: https://www.khaleejtimes.com/business/realty/price-surge-may-moderate-as-dubai-set-to-add-72000-housing-units | J15: Betterhomes
A16: =TEXT(B16, "MMMM") -> January | B16: 45672 | C16: Tier 2 | D16: Zawya | E16: 1000 | F16: 100000 | G16: FY2024 Dubai real estate market highlights: A year of growth and transition | H16: https://www.zawya.com/en/press-release/research-and-studies/fy2024-dubai-real-estate-market-highlights-a-year-of-growth-and-transition-esni838i | J16: Betterhomes
A17: =TEXT(B17, "MMMM") -> January | B17: 45674 | C17: Tier 3 | D17: MENAFN | G17: Price Surge May Moderate As Dubai Set To Add 72,000 Housing Units | H17: https://menafn.com/1109100000/Price-Surge-May-Moderate-As-Dubai-Set-To-Add-72000-Housing-Units | J17: Betterhomes
A18: =TEXT(B18, "MMMM") -> January | B18: 45678 | C18: Tier 1 Local | D18: Gulf News | E18: 1000 | F18: 150000 | G18: Buying freehold property in Dubai: Your guide to securing full ownership | H18: https://gulfnews.com/living-in-uae/housing/how-to-buy-freehold-property-in-dubai-how-to-secure-full-ownership-1.500019993 | J18: Betterhomes
A19: =TEXT(B19, "MMMM") -> January | B19: 45678 | C19: Tier 1 Local | D19: Arabian Business | E19: 9500 | F19: 250000 | G19: Dubai villa rent prices surge 52%, Palm Jumeirah sees biggest spike in 2024: Report | H19: https://www.arabianbusiness.com/industries/real-estate/dubai-villa-rent-prices-surge-52-palm-jumeirah-sees-biggest-spike-in-2024-report | J19: Betterhomes
A20: =TEXT(B20, "MMMM") -> January | B20: 45680 | C20: Tier 1 Local | D20: Arabian Business | E20: 9500 | F20: 250000 | G20: Dubai commercial property market records 24% jump in growth, rakes in $24.5bn in value in 2024 | H20: https://www.arabianbusiness.com/industries/real-estate/dubai-commercial-property-market-records-24-jump-in-growth-rakes-in-24-5bn-in-value-in-2024 | J20: Betterhomes/CRC
A21: =TEXT(B21, "MMMM") -> January | B21: 45680 | C21: Tier 3 | D21: mid east info | G21: FY2024 Dubai Real Estate Market Highlights: A Year of Growth and Transition | H21: https://mid-east.info/fy2024-dubai-real-estate-market-highlights-a-year-of-growth-and-transition/ | J21: Betterhomes
A22: =TEXT(B22, "MMMM") -> January | B22: 45680 | C22: Tier 3 | D22: MENAFN | G22: FY2024 Dubai Real Estate Market Highlights: A Year Of Growth And Transition | H22: https://menafn.com/1109122274/FY2024-Dubai-Real-Estate-Market-Highlights-A-Year-Of-Growth-And-Transition | J22: Betterhomes
A23: =TEXT(B23, "MMMM") -> January | B23: 45682 | C23: Tier 3 | D23: MENAFN | G23: A 23% Rise in Tenant Demand at Betterhomes | H23: https://menafn.com/1109127970/A-23-Rise-in-Tenant-Demand-at-Betterhomes | J23: Betterhomes
A24: =TEXT(B24, "MMMM") -> January | B24: 45684 | C24: Tier 1 Local | D24: Khaleej Times | E24: 2200 | F24: 500000 | G24: Dubai: Tenants move to cheaper areas, lock long-term leases before commercial rental index rollout | H24: https://www.khaleejtimes.com/uae/dubai-tenants-relocating-to-cheaper-areas-securing-long-term-leases-ahead-of-commercial-rental-ind?amp=1 | J24: Betterhomes/CRC
A25: =TEXT(B25, "MMMM") -> January | B25: 45685 | C25: Tier 1 Local | D25: Arabian Business | E25: 9500 | F25: 250000 | G25: Dubai real estate: DLD opens freehold property conversion for Sheikh Zayed Road, Al Jaddaf – everything you need to know | H25: https://www.arabianbusiness.com/industries/real-estate/dubai-real-estate-dld-opens-freehold-property-conversion-for-sheikh-zayed-road-al-jaddaf-everything-you-need-to-know?utm_medium=email&utm_medium=email&utm_campaign=UK%20millionaires%20head%20for%20Dubai%20Abu%20Dhabi%20DLD%20freehold%20property%20conversion%20explainer%20UAE%20BNPL%20platforms%20set%20new%20limit%20081603%20AM&utm_content=UK%20millionaires%20head%20for%20Dubai%20Abu%20Dhabi%20DLD%20freehold%20property%20conversion%20explainer%20UAE%20BNPL%20platforms%20set%20new%20limit%20081603%20AM+CID_1576cdc239b534957231a5f1f1d0dd95&utm_source=Newsletters&utm_term=Dubai%20real%20estate%20DLD%20opens%20freehold%20property%20conversion%20for%20Sheikh%20Zayed%20Road%20Al%20Jaddaf%20%20everything%20you%20need%20to%20know | J25: Betterhomes
A26: =TEXT(B26, "MMMM") -> January | B26: 45685 | C26: Tier 1 Local | D26: Khaleej Times | E26: 2200 | F26: 500000 | G26: Dubai rent hikes to slow down in 2025 as property market set for record supply | H26: https://www.khaleejtimes.com/business/realty/dubai-rent-hikes-to-slow-down-in-2025-as-property-market-set-for-record-supply | J26: Betterhomes
A27: =TEXT(B27, "MMMM") -> January | B27: 45685 | C27: Tier 3 | D27: MENAFN | G27: Dubai Rent Hikes To Slow Down In 2025 As Property Market Set For Record Supply | H27: https://menafn.com/1109137391/Dubai-Rent-Hikes-To-Slow-Down-In-2025-As-Property-Market-Set-For-Record-Supply | J27: Betterhomes
A28: =TEXT(B28, "MMMM") -> January | B28: 45685 | C28: Tier 3 | D28: Press Reader | G28: Tenants shifting to cheaper areas as commercial rental index looms | H28: https://www.pressreader.com/uae/khaleej-times/20250128/281651080785914 | J28: Betterhomes
A29: =TEXT(B29, "MMMM") -> January | B29: 45685 | C29: Tier 3 | D29: MENAFN | G29: 2024 Sees Supply Delays as Developers Set Sights on Record-Breaking 2025 Completions | H29: https://menafn.com/1109138635/2024-Sees-Supply-Delays-as-Developers-Set-Sights-on-Record-Breaking-2025-Completions | J29: Betterhomes
A30: =TEXT(B30, "MMMM") -> January | B30: 45686 | C30: Tier 3 | D30: Press Reader | G30: Record supply likely to ease Dubai rents in ’25 | H30: https://www.pressreader.com/uae/khaleej-times/20250129/281638195886222 | J30: Betterhomes
A31: =TEXT(B31, "MMMM") -> February | B31: 45690 | C31: Tier 3 | D31: MENAFN | G31: Investor Confidence Soars as Off-Plan Dominates Dubai’s Residential Real Estate Market in 2024 | H31: https://www.google.com/url?rct=j&sa=t&url=https://menafn.com/1109155855/Investor-Confidence-Soars-as-Off-Plan-Dominates-Dubais-Residential-Real-Estate-Market-in-2024&ct=ga&cd=CAEYACoUMTU5MzQwNzI3MjY2NzM5MzgzOTkyGmYxMGNhMzlmN2NmNGIzNmM6Y29tOmVuOlVT&usg=AOvVaw2_sIONQqVXBX_dd-Hp5QSc | J31: Betterhomes
A32: =TEXT(B32, "MMMM") -> February | B32: 45691 | C32: Tier 1 Local | D32: Arabian Business | E32: 9500 | F32: 250000 | G32: Dubai real estate: High-end villas, luxury apartments to lead city’s rental price gains in 2025 | H32: https://www.arabianbusiness.com/industries/real-estate/dubai-real-estate-high-end-villas-luxury-apartments-to-lead-citys-rental-price-gains-in-2025 | J32: Betterhomes
A33: =TEXT(B33, "MMMM") -> February | B33: 45692 | C33: Tier 1 Local | D33: Khaleej Times | E33: 2200 | F33: 500000 | G33: Dubai: Most tenants renew leases due to high rents, but this could change; here’s why | H33: https://www.khaleejtimes.com/uae/dubai-most-tenants-renew-leases-due-to-high-rents-but-this-could-change-heres-why | J33: Betterhomes
A34: =TEXT(B34, "MMMM") -> February | B34: 45693 | C34: Tier 3 | D34: Property News Time | G34: Dubai Real Estate Market sets new records in 2024 with AED 423.36 Billion in sales | H34: https://www.propnewstime.com/getdetailsStories/MTQ3MTI=/dubai-real-estate-market-sets-new-records-in-2024-with-aed-423-36-billion-in-sales | J34: Betterhomes
A35: =TEXT(B35, "MMMM") -> February | B35: 45693 | C35: Tier 3 | D35: PressReader.com | G35: Tenants prefer lease renewals as new contracts prove costlier | H35: https://www.pressreader.com/uae/khaleej-times/20250205/281522231784879 | J35: Betterhomes
A36: =TEXT(B36, "MMMM") -> February | B36: 45694 | C36: Tier 3 | D36: Property News Time | G36: Dubai's property market set for 171% rise in completions in 2025 | H36: https://www.propnewstime.com/getdetailsStories/MTQ3MTY=/dubai-s-property-market-set-for-171-rise-in-completions-in-2025 | J36: Betterhomes
A37: =TEXT(B37, "MMMM") -> February | B37: 45694 | C37: Tier 2 | D37: Zawya | E37: 1000 | F37: 100000 | G37: Dubai’s property market kicks off 2025 with a bang: AED 35bln in sales | H37: https://www.zawya.com/en/press-release/research-and-studies/dubais-property-market-kicks-off-2025-with-a-bang-aed-35bln-in-sales-ydbkolcn | J37: Betterhomes
A38: =TEXT(B38, "MMMM") -> February | B38: 45693 | C38: Tier 1 International | D38: The Guardian | E38: 9000 | F38: 700000 | G38: Dubai: Buying the Dream | H38: https://www.theguardian.com/tv-and-radio/2025/feb/05/tv-tonight-the-hilarious-spin-off-from-sharon-horgans-motherland | J38: Betterhomes
A39: =TEXT(B39, "MMMM") -> February | B39: 45695 | C39: Tier 1 Local | D39: Arabian Business | E39: 9500 | F39: 250000 | G39: Dubai real estate: Average prices for apartments, townhouses and villas revealed as sales hit $9.5bn in January | H39: https://www.arabianbusiness.com/industries/real-estate/dubai-real-estate-average-prices-for-apartments-townhouses-and-villas-revealed-as-sales-hit-9-5bn-in-january | J39: Betterhomes
A40: =TEXT(B40, "MMMM") -> February | B40: 45697 | C40: Tier 1 Local | D40: Khaleej Times | E40: 2200 | F40: 500000 | G40: Dubai’s realty off to strong start with Dh35b first month sales | H40: https://www.khaleejtimes.com/business/dubais-realty-off-to-strong-start-with-dh35b-first-month-sales | J40: Betterhomes
...

Sheet Pivot Table 2

Sheet 2023
A1: Date | B1: Media Tier | C1: Media | D1: Title | E1: Link | F1: Brand
A2: 44941 | B2: Tier 1 | C2: Thomson Reuters | D2: Dubai property price rises may slow further in 2023, real-estate consultancy says | E2: https://www.reuters.com/world/middle-east/dubai-property-price-rises-seen-slowing-further-2023-betterhomes-2023-01-15/ | F2: Betterhomes
A3: 44941 | B3: Tier 3 | C3: Latest LY | D3: Dubai Property Price Rises Seen Slowing Further in 2023 - Betterhomes | E3: https://www.latestly.com/socially/sports/cricket/virat-kohli-does-a-ms-dhoni-star-india-batter-hits-helicopter-shot-for-six-in-ind-vs-sl-3rd-odi-2023-watch-video-4716180.html | F3: Betterhomes
A4: 44941 | B4: Tier 3 | C4: Zone Bourse (France) | D4: Dubai property price growth set to slow further in 2023 | E4: https://www.zonebourse.com/actualite-bourse/La-hausse-des-prix-de-l-immobilier-a-Dubai-devrait-encore-ralentir-en-2023-Betterhomes--42738330/?utm_medium=RSS&utm_content=20230115 | F4: Betterhomes
A5: 44941 | B5: Tier 2 | C5: Khaleej Times | D5: Dubai property price rises seen slowing further in 2023: Betterhomes | E5: https://www.khaleejtimes.com/business/dubai-property-price-rises-seen-slowing-further-in-2023-betterhomes | F5: Betterhomes
A6: 44942 | B6: Tier 3 | C6: Manager (Bulgaria) | D6: Russians have become the biggest buyers of luxury properties in Dubai | E6: https://manager.bg/%D0%B1%D0%B8%D0%B7%D0%BD%D0%B5%D1%81/rusnacite-stanaha-nai-golemite-kupuvachi-na-luksozni-imoti-v-dubai | F6: Betterhomes
A7: 44942 | B7: Tier 3 | C7: Titulares (Spain) | D7: Dubai reaches record number of real estate transactions of more than $143,000 million after years of crisis | E7: https://titulares.ar/dubai-alcanza-cifra-record-de-transacciones-inmobiliarias-de-mas-de-143-000-millones-tras-anos-de-crisis/ | F7: Betterhomes
A8: 44942 | B8: Tier 3 | C8: Foco (Spain) | D8: Why did Dubai achieve record real estate transactions in 2022? | E8: https://foco.lanacion.com.py/2023/01/16/por-que-dubai-logro-record-de-transacciones-inmobiliarias-en-2022/ | F8: Betterhomes
A9: 44942 | B9: Tier 2 | C9: Arab News | D9: UAE In-Focus — US, UAE allocate $20bn to fund 15 GW of clean energy projects | E9: https://www.arabnews.com/node/2233301/business-economy | F9: Betterhomes
A10: 44942 | B10: Tier 3 | C10: Dagens Industri (Sweeden) | D10: Russian money drugs Dubai's real estate market - reaches new record level | E10: https://www.di.se/live/ryska-pengar-dopar-dubais-fastighetsmarknad-nar-ny-rekordniva/ | F10: Betterhomes
A11: 44942 | B11: Tier 3 | C11: Finanzemarkt (Germany) | D11: Real estate: That's how massive Russian money is pouring into Dubai | E11: https://finanzmarktwelt.de/immobilien-so-massiv-stroemt-russisches-geld-nach-dubai-258253/ | F11: Betterhomes
A12: 44942 | B12: Tier 3 | C12: Il Matinno (Italy) | D12: Abramovich, Rybolovlev and the others: the anti-sanctions moves. Here's how (and how much) Russian oligarchs invest in Dubai | E12: https://www.ilmattino.it/primopiano/esteri/abramovich_oligarchi_russi_investimenti_dubai_cosa_sta_succedendo-7173231.html | F12: Betterhomes
A13: 44942 | B13: Tier 1 | C13: Forbes (Ukarain) | D13: Property sales in Dubai have risen to a record high due to an increase in the number of buyers from Russia | E13: https://forbes.ua/news/prodazh-nerukhomosti-v-dubai-zris-do-rekordnogo-rivnya-cherez-zbilshennya-kilkosti-pokuptsiv-z-rosii-16012023-11091 | F13: Betterhomes
... A180: 45135 | B180: Tier 2 | C180: Time Out Dubai | D180: House-hunting? Download these real estate apps in Dubai | E180: https://www.timeoutdubai.com/moving-to-dubai/real-estate-apps-in-dubai | F180: Betterhomes
A181: 45136 | B181: Tier 3 | C181: Watson (France) | D181: From Switzerland to Dubai: Russian oligarchs move their money | E181: https://www.watson.ch/fr/economie/russie/982986502-de-la-paradeplatz-a-dubai-les-riches-russes-deplacent-leur-argent
A182: 45137 | B182: Tier 3 | C182: Prian (Russia) | D182: The most Russian districts of Dubai: where investors from the Russian Federation buy real estate | E182: https://prian.ru/pub/samye-russkie-rayony-dubaya-gde-pokupayut-nedvizhimost-investory-iz-rf.html | F182: Betterhomes
A183: 45138 | B183: Tier 2 | C183: The National | D183: What's next for the Dubai property market? | E183: https://www.thenationalnews.com/weekend/2023/07/28/whats-next-for-the-dubai-property-market/ | F183: Betterhomes
A184: 45140 | B184: Tier 2 | C184: Khaleej Times | D184: Rents in Dubai: Up to Dh20,000 discount on fewer cheque payments | E184: https://www.khaleejtimes.com/life-and-living/housing-in-uae/rents-in-dubai-up-to-dh20000-discount-on-fewer-cheque-payments?_refresh=true | F184: Betterhomes
A185: 45140 | B185: Tier 2 | C185: Zawya | D185: Rents in Dubai: Up to $5,500 discount on fewer cheque payments | E185: https://www.zawya.com/en/business/real-estate/rents-in-dubai-up-to-5-500-discount-on-fewer-cheque-payments-snyex3vu | F185: Betterhomes
A186: 45141 | B186: Tier 2 | C186: Khaleej Times | D186: How is off-plan investment different from investing in ready properties? | E186: https://www.khaleejtimes.com/business/how-is-off-plan-investment-different-from-investing-in-ready-properties#:~:text=Unlike%20off%2Dplan%20investments%2C%20ready,in%20the%20completion%20of%20construction. | F186: Betterhomes
A187: 45153 | B187: Tier 1 | C187: CNN | D187: Which is better.. buying or renting real estate? The experts answer | E187: https://cnnbusinessarabic.com/real-estate-construction/34375/%D8%A3%D9%8A%D9%87%D9%85%D8%A7-%D8%A3%D9%81%D8%B6%D9%84-%D8%B4%D8%B1%D8%A7%D8%A1-%D8%A7%D9%84%D8%B9%D9%82%D8%A7%D8%B1%D8%A7%D8%AA-%D8%A3%D9%85-%D8%A7%D8%B3%D8%AA%D8%A6%D8%AC%D8%A7%D8%B1%D9%87%D8%A7%D8%9F-%D8%A7%D9%84%D8%AE%D8%A8%D8%B1%D8%A7%D8%A1-%D9%8A%D8%AC%D9%8A%D8%A8%D9%88%D9%86 | F187: Betterhomes
A188: 45155 | B188: Tier 2 | C188: Mena FN | D188: The Surge Of Custom-Built Villas In Palm Jumeirah: Unveiling The Trend And Its Motivations | E188: https://menafn.com/1106880144/The-Surge-Of-Custom-Built-Villas-In-Palm-Jumeirah-Unveiling-The-Trend-And-Its-Motivations | F188: Betterhomes
A189: 45155 | B189: Tier 2 | C189: Khaleej Times | D189: The Surge Of Custom-Built Villas In Palm Jumeirah: Unveiling The Trend And Its Motivations | E189: https://www.khaleejtimes.com/business/the-surge-of-custom-built-villas-in-palm-jumeirah-unveiling-the-trend-and-its-motivations | F189: Betterhomes
A190: 45155 | B190: Tier 2 | C190: The National | D190: Where are the best places to live in Dubai with children? | E190: https://www.thenationalnews.com/uae/2023/08/24/best-area-live-dubai-family/ | F190: Betterhomes
A191: 45156 | B191: Tier 3 | C191: Russia Matters | D191: Russia in Review | E191: https://www.russiamatters.org/news/russia-review/russia-review-aug-18-25-2023 | F191: Betterhomes
A192: 45156 | B192: Tier 2 | C192: Business Insider | D192: Russia's economic woes have led to a flood of cash and sparked a real estate boom in the United Arab Emirates | E192: https://www.businessinsider.de/politik/international-politics/russlands-wirtschaftliche-probleme-haben-zu-flut-von-bargeld-gefuehrt-und-immobilienboom-in-den-vereinigten-arabischen-emiraten-ausgeloest/ | F192: Betterhomes
A193: 45159 | B193: Tier 1 | C193: The Wall Street Journal | D193: U.A.E. Cashes In on Russia’s Economic Woes | E193: https://www.wsj.com/world/russia/u-a-e-cashes-in-on-russias-economic-woes-52700157 | F193: Betterhomes
... A285: 45285 | B285: Tier 2 | C285: Zawya | D285: Dubai property owners increasingly opting for flipping as prices hit all-time high | E285: https://www.zawya.com/en/business/real-estate/dubai-property-owners-increasingly-opting-for-flipping-as-prices-hit-all-time-high-gowl4ibz | F285: Betterhomes
B471: Tier 2
B472: Tier 2

Sheet 2022
A1: Date | B1: Media Tier | C1: Media | D1: Title | E1: Link | F1: Brand
A2: 44586 | B2: Tier 2 | C2: Zawya | D2: CRC, Betterhomes Group company and Dubai's largest commercial real estate agency, released their 2021 Dubai Commercial Property Market Report | E2: https://www.zawya.com/uae/en/story/amp/ZAWYA20220125075208/ | F2: CRC
A3: 44587 | B3: Tier 2 | C3: Property News | D3: Betterhomes: Dubai real estate at all-time high after banner year in 2021 | E3: https://www.propertynews.ae/general/press-release/betterhomes-dubai-real-estate-at-all-time-high-after-banner-year-in-2021/ | F3: Betterhomes
A4: 44588 | B4: Tier 2 | C4: Khaleej Times | D4: Dubai: Real estate boom to continue; 36,000 residential units to come online in 2022 | E4: https://www.khaleejtimes.com/property/dubai-real-estate-boom-to-continue-36000-residential-units-to-come-online-in-2022 | F4: Betterhomes
A5: 44598 | B5: Tier 2 | C5: Arabian Business | D5: 2021 seen as ‘major turning point’ for Dubai office market after Covid shock | E5: https://www.arabianbusiness.com/industries/real-estate/2021-seen-as-major-turning-point-for-dubai-office-market-after-covid-shock | F5: CRC
A6: 44638 | B6: Tier 2 | C6: The National | D6: Top 7 mistakes to avoid when selling your home | E6: https://www.thenationalnews.com/weekend/2022/03/18/top-7-mistakes-to-avoid-when-selling-your-home/ | F6: Betterhomes
A7: 44669 | B7: Tier 2 | C7: Zawya | D7: Demand and prices on the rise for townhouses and apartments in Q1 2022 | E7: https://www.zawya.com/en/press-release/companies-news/demand-and-prices-on-the-rise-for-townhouses-and-apartments-in-q1-2022-dp9dk0s7 | F7: Betterhomes
A8: 44670 | B8: Tier 2 | C8: Gulf News | D8: In Dubai, villa owners find no takers for sudden price hikes of 10% and more | E8: https://gulfnews.com/business/property/in-dubai-villa-owners-find-no-takers-for-sudden-price-hikes-of-10-and-more-1.1650345406229 | F8: Betterhomes
A9: 44670 | B9: Tier 1 | C9: Bloomberg | D9: Russians Climb Dubai Property Ladder as Sanctions Imperil Wealth | E9: https://www.bloomberg.com/news/articles/2022-04-19/russians-climb-dubai-property-ladder-as-sanctions-imperil-wealth | F9: Betterhomes
A10: 44671 | B10: Tier 2 | C10: Arabian Business | D10: Dubai’s commercial property market soars as post Covid confidence leads to strongest quarter since 2016 | E10: https://www.arabianbusiness.com/money/wealth/money-wealth-real-estate/dubais-commercial-property-market-soars-as-post-covid-confidence-leads-to-strongest-quarter-since-2016 | F10: CRC
A11: 44673 | B11: Tier 2 | C11: The National | D11: Five renovations that could actually lower the value of your home | E11: https://www.thenationalnews.com/weekend/2022/04/22/five-renovations-that-could-actually-lower-the-value-of-your-home/ | F11: Betterhomes
A12: 44676 | B12: Tier 2 | C12: Arab news | D12: Dubai property purchases by Russians up 67% in Q1 of 2022 | E12: https://www.arabnews.com/node/2066971/business-economy | F12: Betterhomes
A13: 44676 | B13: Tier 1 | C13: Bloomberg | D13: Rising Oil Prices a Boon for Saudi Economy | E13: https://www.bloomberg.com/news/newsletters/2022-04-25/rising-oil-prices-a-boon-for-saudi-arabia-s-economy | F13: Betterhomes
... A89: 44783 | B89: Tier 1 | C89: Thomson Reuters | D89: Major Gulf bourses trade mixed; Abu Dhabi at record high | E89: https://www.reuters.com/world/middle-east/major-gulf-bourses-trade-mixed-abu-dhabi-record-high-2022-08-10/ | F89: Betterhomes
A90: 44783 | B90: Tier 2 | C90: Gulf News | D90: As rents rise 20-30%, more Dubai residents see better value in renewing contracts than chase new ones | E90: https://gulfnews.com/business/property/as-rents-rise-20-30-more-dubai-residents-see-better-value-in-renewing-contracts-than-chase-new-ones-1.1660102666420 | F90: Betterhomes | J90: #ef6078ff
A91: 44783 | B91: Tier 3 | C91: Bdnews24 (Bangladesh) | D91: Dubai's biggest bank gives staff a pay rise for inflation | E91: https://bdnews24.com/economy/pg5abbgrnq | F91: Betterhomes
A92: 44783 | B92: Tier 2 | C92: Arab News | D92: MIDEAST STOCKS-Major Gulf bourses trade mixed; Abu Dhabi at record high | E92: https://www.arabnews.com/node/2139816/business-economy | F92: Betterhomes
A93: 44784 | B93: Tier 3 | C93: Financial Investor | D93: Ryan Mahoney (Dubai, UAE): The CRC Commercial Property Market Report FY 2021 | E93: https://www.financialinvestor24.com/property/1903/ryan-mahoney-dubai-uae-the-crc-commercial-property-market-report-fy-2021/ | F93: CRC
A94: 44785 | B94: Tier 2 | C94: The National News | D94: How ‘Fomo’ is driving UAE residents to take out mortgages while they still can | E94: https://www.thenationalnews.com/weekend/2022/08/12/fomo-drives-uae-residents-to-take-out-mortgages-amid-rate-rises/ | F94: Betterhomes
A95: 44785 | B95: Tier 3 | C95: El Correo del Golfo (Spain) | D95: The largest bank in Dubai raises the salary of its employees | E95: https://www.elcorreo.ae/articulo/economia/banco-mas-grande-dubai-sube-sueldo-empleados/20220812090626148406.html | F95: Betterhomes
A96: 44787 | B96: Tier 2 | C96: Khaleej TImes | D96: New tenants to pay higher rents in Dubai | E96: https://www.khaleejtimes.com/business/new-tenants-to-pay-higher-rents-in-dubai | F96: Betterhomes
A97: 44788 | B97: Tier 2 | C97: Zawya | D97: New tenants to pay higher rents in Dubai | E97: https://www.zawya.com/en/business/real-estate/new-tenants-to-pay-higher-rents-in-dubai-tppmufae | F97: Betterhomes
A98: 44789 | B98: Tier 2 | C98: Gulf News | D98: Travelling for a month or two - can I put up my Dubai home for rent? | E98: https://gulfnews.com/living-in-uae/housing/travelling-for-a-month-or-two---can-i-put-up-my-dubai-home-for-rent-1.1660661106061 | F98: STR BH
A99: 44789 | B99: Tier 3 | C99: News Week (US) | D99: Wealthy Russians Are Racing To Buy Homes in Turkey—Here's Why | E99: https://www.newsweek.com/wealthy-russians-racing-buy-homes-turkey-why-explained-1734028 | F99: Betterhomes
A100: 44789 | B100: Tier 3 | C100: The Latest News (Germany) | D100: Wealthy Russians are racing to buy houses in Turkey — here's why | E100: https://www.theaktuellenews.com/nachrichten/wohlhabende-russen-rennen-um-den-kauf-von-haeusern-in-der-tuerkei-hier-ist-der-grund/ | F100: Betterhomes
A101: 44790 | B101: Tier 2 | C101: Zawya | D101: Dubai: Real estate firm’s name, escrow account, other details must on ads | E101: https://www.zawya.com/en/business/real-estate/dubai-real-estate-firms-name-escrow-account-other-details-must-on-ads-axl3oipj | F101: Betterhomes
A102: 44790 | B102: Tier 3 | C102: Ahval (Turkey) | D102: Wealthy Russians vying to purchase homes in Turkey | E102: https://ahvalnews.com/turkish-property/wealthy-russians-vying-purchase-homes-turkey | F102: Betterhomes
... A203: 44926 | B203: Tier 2 | C203: Gulf News | D203: UAE Corporate Tax: Businesses have some early preparations to do | E203: https://gulfnews.com/business/analysis/uae-corporate-tax-businesses-have-some-early-preparations-to-do-1.92961154 | F203: OpenHub

Sheet 2021
A1: Date | B1: Media Tier | C1: Media | D1: Title | E1: Link | F1: Brand
A2: 44197 | B2: - | C2: Better Living Magazine | D2: Hot properties | E2: Print | F2: Betterhomes
A3: 44256 | B3: - | C3: Better Living Magazine | D3: Hot properties | E3: Print | F3: Betterhomes
A4: 44308 | B4: Tier 3 | C4: PR.com | D4: Betterhomes Released Residential Property Market Report Q1 2021 | E4: https://www.pr.com/press-release/835148 | F4: Betterhomes
A5: 44308 | B5: Tier 2 | C5: Khaleej Times | D5: Dubai records 27% surge in Q1 property deals | E5: https://www.khaleejtimes.com/news/dubai-records-27-surge-in-q1-property-deals | F5: Betterhomes
A6: 44308 | B6: Tier 3 | C6: Springfiled properties | D6: Dubai records 27% surge in Q1 property deals | E6: https://www.springfield-re.com/dubai-records-27-surge-in-q1-property-deals | F6: Betterhomes
A7: 44321 | B7: Tier 3 | C7: Creativezone | D7: Dubai Real Estate: A 2021 Promising Outlook | E7: https://www.creativezone.ae/events/dubai-real-estate-a-2021-promising-outlook/ | F7: Betterhomes
A8: 44321 | B8: - | C8: Better Living Magazine | D8: Hot properties | E8: Print | F8: Betterhomes
A9: 44378 | B9: - | C9: Better Living Magazine | D9: Hot properties | E9: Print | F9: Betterhomes
A10: 44411 | B10: Tier 2 | C10: Zawaya | D10: Positive economic & employment sentiment in Dubai boosts property sales in H1 2021 | E10: https://www.zawya.com/uae/en/press-releases/story/Positive_economic__employment_sentiment_in_Dubai_boosts_property_sales_in_H1_2021-ZAWYA20210803062005/ | F10: Betterhomes
A11: 44411 | B11: Tier 2 | C11: Arabian Business | D11: Dubai broker sees surge in British property buyers amid UAE's latest expat incentives | E11: https://www.arabianbusiness.com/real-estate/466741-dubai-broker-sees-surge-in-british-property-buyers-amid-uaes-latest-expat-incentives | F11: Betterhomes
A12: 44411 | B12: Tier 2 | C12: Khaleej Times | D12: Dubai realty back in spotlight with deals hitting 10-year high | E12: https://www.khaleejtimes.com/property/dubai-realty-back-in-spotlight-with-deals-hitting-10-year-high | F12: Betterhomes
A13: 44440 | B13: - | C13: Better Living Magazine | D13: Hot properties | E13: Print | F13: Betterhomes
... A33: 44504 | B33: Tier 2 | C33: Property Finder | D33: Latest Prestige November 2021 issue in Gulf Business | E33: https://www.propertyfinder.ae/hub/agent-guides/latest-prestige-november-2021-issue-in-gulf-business/ | F33: Linda's
A34: 44506 | B34: Tier 2 | C34: The National | E34: https://www.thenationalnews.com/lifestyle/luxury/2021/11/06/dh75m-emirates-hills-villa-becomes-dubais-most-expensive-rental/ | F34: Betterhomes
A35: 44506 | B35: Tier 2 | C35: Radio Eye | D35: Hannah's 7.5m leasinf deal | E35: Business Breakfast | F35: Betterhomes
A36: 44507 | B36: Tier 2 | C36: Construction Week | D36: Betterhomes logs leasing deal at $1.76 million in Emirates Hills | E36: https://www.constructionweekonline.com/business/betterhomes-logs-leasing-deal-at-1-76-million-in-emirates-hills | F36: Betterhomes
A37: 44508 | B37: Tier 3 | C37: The Wall | E37: https://thewall.fyi/dubai-property-broker-seals-record-2m-leasing-deal-for-luxury-villa/ | F37: Betterhomes
A38: 44509 | B38: Tier 3 | C38: International Business Magazine | E38: https://intlbm.com/dubai-real-estate-market-clocks-its-highest-leasing-deal-worth-aed7-5-million/ | F38: Betterhomes
A39: 44509 | B39: Tier 3 | C39: Medium Value Strat | E39: https://medium.com/@valustrat/dh7-5m-emirates-hills-villa-becomes-dubais-most-expensive-rental-fdd55e5c53bd | F39: Betterhomes

Sheet 2024
A1: Date | B1: Media Tier | C1: Media | D1: Cost | E1: Reach | F1: Title | G1: Link | H1: Brand
A2: 45294 | B2: Tier 2 | C2: Construction Week | D2: 3000 | E2: 40000 | F2: The next wave: Top Dubai real estate trends forecasted in 2024 | G2: https://www.constructionweekonline.com/analysis/the-next-wave-top-dubai-real-estate-trends-forecasted-in-2024 | H2: Betterhomes
A3: 45299 | B3: Tier 2 | C3: Arabian Business | D3: 9500 | E3: 250000 | F3: Dubai real estate: Should you buy a timeshare? Experts weigh in | G3: https://www.arabianbusiness.com/industries/real-estate/dubai-real-estate-should-you-buy-a-timeshare-experts-weigh-in?utm_source=onesignal&utm_medium=push-notification&utm_campaign=pushnotification-traffic | H3: Betterhomes
A4: 45301 | B4: Tier 3 | C4: Super Guide Veronica (Netherlands) | F4: Dubai: Buying the Dream | G4: https://www.veronicasuperguide.nl/tv-tips/dubai-buying-the-dream?referrer=https%3A%2F%2Fwww.google.com%2F | H4: Betterhomes
A5: 45303 | B5: Tier 3 | C5: Business Insider India | F5: The Indian rich is buying property in Dubai – Tax benefits to rental yields, the driving forces at play | G5: https://www.businessinsider.in/personal-finance/news/the-indian-rich-is-buying-property-in-dubai-tax-benefits-to-rental-yields-the-driving-forces-at-play/articleshow/106767921.cms | H5: Betterhomes
A6: 45303 | B6: Tier 1 | C6: Mansion Global | D6: 10000 | E6: 1500000 | F6: Indian Buyers Drove International Sales in Dubai Last Year | G6: https://www.mansionglobal.com/articles/mansion-global-daily-tinder-co-founder-selling-modern-los-angeles-mansion-e5ce92bb | H6: Betterhomes
A7: 45306 | B7: Tier 2 | C7: Zawya | D7: 1000 | E7: 100000 | F7: Chestertons MENA appoints Rachel Soriano as Director of Training and Development | G7: https://www.zawya.com/en/press-release/people-in-the-news/chestertons-mena-appoints-rachel-soriano-as-director-of-training-and-development-o6fpwo0i | H7: Betterhomes
A8: 45306 | B8: Tier 3 | C8: Gulf Daily News - Bahrain | F8: Chestertons Mena names new training, development head | G8: https://www.gdnonline.com/Details/1300467 | H8: Betterhomes
A9: 45307 | B9: Tier 3 | C9: minfin.com.ua - Ukraine | F9: Sales of real estate in Dubai worth more than $25 million have doubled in a year | G9: https://minfin.com.ua/ua/2024/01/16/119753042/ | H9: Betterhomes
A10: 45308 | B10: Tier 3 | C10: Super Guide Veronica (Netherlands) | F10: Veronica Superguide's viewing tips for your TV evening: Steenrijk, Straatarm, Dubai: Buying the Dream and DNA Unknown | G10: https://www.veronicasuperguide.nl/nieuws/veronica-superguide-s-kijktips-voor-je-tv-avond-steenrijk-straatarm-dubai-buying-the-dream-en-dna-onbekend | H10: Betterhomes
A11: 45309 | B11: Tier 2 | C11: Khaleej Times | D11: 2200 | E11: 500000 | F11: Dubai property: End-users continue to rise | G11: https://www.khaleejtimes.com/hi/business/dubai-property-end-users-continue-to-rise | H11: Betterhomes
A12: 45310 | B12: Tier 2 | C12: Zawya | D12: 1000 | E12: 100000 | F12: Dubai property: End-users continue to rise | G12: https://www.zawya.com/en/business/real-estate/dubai-property-end-users-continue-to-rise-rhis0tpn | H12: Betterhomes
A13: 45311 | B13: Tier 2 | C13: Arabian Business | D13: 9500 | E13: 250000 | F13: Dubai real estate: Property sales shatter records in 2023 with over 120,000 transactions, says new report | G13: https://www.arabianbusiness.com/industries/real-estate/dubai-real-estate-property-sales-shatter-records-in-2023-with-over-120000-transactions-says-new-report | H13: Betterhomes
A14: 45312 | B14: Tier 3 | C14: Le Petit Journal (France) | F14: Real estate in Dubai: Real estate sales hit records in 2023 | G14: https://lepetitjournal.com/dubai/logement/immobilier-dubai-ventes-immobilieres-records-2023-377186 | H14: Betterhomes
A15: 45313 | B15: Tier 2 | C15: The National News | D15: 9300 | E15: 200000 | F15: One-cheque payments increasingly common in Dubai rental market | G15: https://www.thenationalnews.com/business/property/2024/01/20/one-cheque-payments-increasingly-common-in-dubai-rental-market/ | H15: Betterhomes
A16: 45313 | B16: Tier 2 | C16: Zawya | D16: 1000 | E16: 100000 | F16: Indians, Russians and British buyers are Dubai's top property investors in 2023 | G16: https://www.zawya.com/en/business/real-estate/indians-russians-and-british-buyers-are-dubais-top-property-investors-in-2023-lq6layv5 | H16: Betterhomes
A17: 45313 | B17: Tier 3 | C17: Bol News (Pakistan) | F17: Indians top Dubai real estate market, surpass Russians for first time | G17: https://www.bolnews.com/latest/2024/01/indians-top-dubai-real-estate-market-surpass-russians-for-first-time/ | H17: Betterhomes
A18: 45313 | B18: Tier 3 | C18: Business Recorder (Pakistan) | F18: 2023: Pakistanis remain among top 10 buyers of Dubai property, Indians top list | G18: https://www.brecorder.com/news/40285061 | H18: Betterhomes
A19: 45313 | B19: Tier 2 | C19: The National News | D19: 9300 | E19: 200000 | F19: Dubai developer Deyaar's 2023 profit jumps over threefold on higher revenue | G19: https://www.thenationalnews.com/business/markets/2024/01/22/dubai-developer-deyaars-2023-profit-jumps-over-threefold-on-higher-revenue/ | H19: Betterhomes
A20: 45315 | B20: Tier 2 | C20: The National News | D20: 9300 | E20: 200000 | F20: Dubai developers entice new buyers with favourable payment terms | G20: https://www.thenationalnews.com/business/property/2024/01/24/dubai-developers-entice-new-buyers-with-favourable-payment-terms/ | H20: Betterhomes
A21: 45315 | B21: Tier 2 | C21: The National News | D21: 9300 | E21: 200000 | F21: Golden visas: UAE 'cancels minimum down payment' for property investors | G21: https://www.thenationalnews.com/business/money/2024/01/24/golden-visa-dubai-property/ | H21: Betterhomes
A22: 45315 | B22: Tier 2 | C22: What's On | F22: UAE Golden Visa: Minimum down-payment no longer required for property investors | G22: https://whatson.ae/2024/01/uae-golden-visa-minimum-down-payment-no-longer-required-for-property-investors/ | H22: Betterhomes
A23: 45317 | B23: Tier 3 | C23: Investing.com | F23: Analysis-Dubai's property boom shows signs of fizzling out | G23: https://www.investing.com/news/stock-market-news/analysisdubais-property-boom-shows-signs-of-fizzling-out-3283664 | H23: Betterhomes
A24: 45317 | B24: Tier 1 | C24: Reuters | D24: 20000 | E24: 1000000 | F24: Dubai's property boom shows signs of fizzling out | G24: https://www.reuters.com/world/middle-east/dubais-property-boom-shows-signs-fizzling-out-2024-01-26/ | H24: Betterhomes
A25: 45317 | B25: Tier 3 | C25: The Edge Malaysia | F25: Dubai's property boom shows signs of fizzling out | G25: https://www.investing.com/news/stock-market-news/analysisdubais-property-boom-shows-signs-of-fizzling-out-3283664 | H25: Betterhomes
A26: 45317 | B26: Tier 3 | C26: IG (Ishradgul News) | F26: Dubai property boom shows signs of abating – Business & Finance IG News | G26: https://irshadgul.com/dubai-property-boom-shows-signs-of-abating-business-finance-ig-news/ | H26: Betterhomes
A27: 45317 | B27: Tier 3 | C27: Pi | F27: Dubai property boom shows signs of abating – Business & Finance IG News | G27: https://proiqra.com/dubais-real-estate-boom-shows-signs-of-faltering-business-finance-pi-news/ | H27: Betterhomes
A28: 45318 | B28: Tier 3 | C28: Gulf -Times | F28: Dubai’s property boom shows signs of fizzling out | G28: https://www.gulf-times.com/article/676262/opinion/dubais-property-boom-shows-signs-of-fizzling-out | H28: Betterhomes
A29: 45321 | B29: Tier 2 | C29: Zawya | D29: 1000 | E29: 100000 | F29: Top property management companies for renting homes in Dubai: who are they and why are they needed? | G29: https://www.zawya.com/en/press-release/research-and-studies/top-property-management-companies-for-renting-homes-in-dubai-who-are-they-and-why-are-they-needed-j3lw28q2 | H29: Betterhomes
A30: 45324 | B30: Tier 2 | C30: The National News | D30: 9300 | E30: 200000 | F30: Moving to a new home: Here's what you need to know about rent and utility bills | G30: https://www.thenationalnews.com/uae/2024/02/02/moving-to-a-new-home-heres-what-you-need-to-know-about-rent-and-utility-bills/ | H30: Betterhomes
A31: 45327 | B31: Tier 2 | C31: Khaleej Times | D31: 2200 | E31: 500000 | F31: UAE: Despite traffic, tenants move to bigger units in same emirate to enhance lifestyle | G31: https://www.khaleejtimes.com/business/realty/uae-despite-traffic-tenants-move-to-bigger-units-in-same-emirate-to-enhance-lifestyle | H31: Betterhomes
A32: 45327 | B32: Tier 3 | C32: Times Now (India) | F32: Is Dubai's Property Market Surge Fuelled By Indian Investors? | G32: https://www.timesnownews.com/india/is-dubais-property-market-surge-fuelled-by-indian-investors-article-107430142 | H32: Betterhomes
A33: 45338 | B33: Tier 2 | C33: CBS4 News | F33: Leading Real Estate Experts to Headline IPS 2024 | G33: https://cbs4indy.com/business/press-releases/ein-presswire/689099087/leading-real-estate-experts-to-headline-ips-2024/ | H33: Betterhomes
A34: 45340 | B34: Tier 2 | C34: Khaleej Times | D34: 2200 | E34: 500000 | F34: UAE: Golden Visa demand growing among European property investors | G34: https://www.khaleejtimes.com/business/realty/uae-golden-visa-demand-growing-among-european-property-investors
A35: 45340 | B35: Tier 3 | C35: Menafn | F35: Leading Real Estate Experts to Headline IPS 2024 | G35: https://menafn.com/1107865247/Leading-Real-Estate-Experts-to-Headline-IPS-2024
A36: 45344 | B36: Tier 2 | C36: Khaleej Times | D36: 2200 | E36: 500000 | F36: Up to 200% price increase: Why Dubai property buyers are now selling homes | G36: https://www.khaleejtimes.com/business/realty/up-to-200-return-dubai-property-turning-sellers-market-as-investors-take-advantage-of-3-year-pric | H36: Betterhomes
A37: 45344 | B37: Tier 2 | C37: The Circuit | F37: Russian buyers and a post-pandemic bump have also spurred house sales in the UAE. | G37: https://circuit.news/2024/02/22/dubai-now-a-sellers-market-after-surge-in-property-transactions/ | H37: Betterhomes
A38: 45344 | B38: Tier 2 | C38: The Circuit | F38: The Daily Circuit | G38: https://circuit.news/2024/02/22/the-daily-circuit-dubai-property-a-sellers-market-qatar-fishes-for-startups/ | H38: Betterhomes
A39: 45345 | B39: Tier 2 | C39: Akhbrna News | F39: Dubai announces up to a 200% increase in property prices | G39: https://english.akhbrna.co/uae-news/dubai-announces-up-to-a-200 | H39: Betterhomes
A40: 45345 | B40: Tier 3 | C40: PressReader | F40: Covid property buyer reap profit | G40: PressReader.com - Digital Newspaper & Magazine Subscriptions | H40: Betterhomes
...

Sheet 2020
A1: Date | B1: Media Tier | C1: Media | D1: Title | E1: Link | F1: Brand
A2: 43935 | B2: - | C2: Trade Arabia | D2: Business as usual for movers in Dubai amid lockdown | E2: http://tradearabia.com/news/CONS_366645.html | F2: Betterhomes
A3: 44009 | B3: - | C3: Khaleej Times | D3: Residential rents in Dubai see a sharp drop, especially in these areas | E3: https://www.khaleejtimes.com/business/real-estate/residential-rents-in-dubai-see-a-sharp-drop-especially-in-these-areas-- | F3: Betterhomes
A4: 44042 | B4: - | C4: Zawaya | D4: How Dubai's new Route 2020 will drive demand for residential, commercial properties | E4: https://www.zawya.com/mena/en/business/story/How_Dubais_new_Route_2020_will_drive_demand_for_residential_commercial_properties-ZAWYA20200730052256/ | F4: Betterhomes
A5: 44105 | B5: - | C5: Gulf News | D5: Living in Jumeirah meant compounds with common pools, says Dubai’s villa lady | E5: https://gulfnews.com/business/property/living-in-jumeirah-meant-compounds-with-common-pools-says-dubais-villa-lady-1.1601554872716 | F5: Betterhomes
A6: 44109 | B6: - | C6: Construction Week | D6: Podcast: Dubai's new brokerage for working mothers | E6: https://www.constructionweekonline.com/business/267754-podcast-dubais-new-brokerage-for-working-mothers | F6: Betterhomes
A7: 43831 | B7: - | C7: Arabian Business | D7: The best of the best: All the major award winners from 2019 | E7: https://www.arabianbusiness.com/events/436138-the-best-of-the-best-all-the-major-award-winners-from-2019 | F7: Betterhomes
A8: 43920 | B8: - | C8: Arabian Business | D8: Coronavirus: What impact will Covid-19 have on Dubai's property market? | E8: https://www.arabianbusiness.com/property/443757-coronavirus-what-impact-will-covid-19-have-on-dubais-property-market | F8: Betterhomes
